{
  "comments": [
    {
      "unresolved": true,
      "key": {
        "uuid": "98a09348_ccb4520c",
        "filename": "client/tests/subprocess42_test.py",
        "patchSetId": 1
      },
      "lineNbr": 445,
      "author": {
        "id": 1366072
      },
      "writtenOn": "2021-03-17T00:36:27Z",
      "side": 1,
      "message": "What\u0027s the err in Python3?",
      "range": {
        "startLine": 445,
        "startChar": 20,
        "endLine": 445,
        "endChar": 31
      },
      "revId": "bfdf2ece822f87f4602bab4e7da996d919242de4",
      "serverId": "3ce6091f-6c88-37e8-8c75-72f92ae8dfba"
    }
  ]
}